Workbook

Sheet _top
A1: Page in CVI Tuning Tool | B1: Cvitek Module | C1: Cvitek Driver | D1: Hisilicon | E1: Param2Reg | F1: MPI | G1: Tab | H1: Note | I1: tab | K1: UI Level0 | L1: UI Level1 | M1: UI Level9
A2: Calibration-BLC | B2: Calibration-BLC | D2: BLC | E2: CY | F2: CF | G2: Cali_BlackLevel | J2: BlackLevel
A3: Calibration-LSC | B3: Calibration-LSC | D3: LSC | E3: CY | F3: CF | I3: Cali_RadialShading
A4: Calibration-DPC | B4: Calibration-DPC | D4: DPC | E4: CY | F4: CF | I4: Cali_MeshShading
A5: Calibration-Noise profile | B5: Calibration-Noise profile | D5: Noise profile | E5: CY | F5: CF | G5: Cali_Noise profile
A6: Calibration-AWB | B6: Calibration-AWB | D6: AWB | E6: CY | F6: CF | G6: Cali_AWB
A7: Calibration-CCM | B7: Calibration-CCM | D7: CCM | E7: CY | F7: CF | G7: Cali_CCM | J7: CCM
A8: Calibration-3D-LUT | B8: Calibration-3D-LUT | D8: CLUT | E8: CY | F8: CF | G8: Cali_Clut?
A9: Calibration-AE LV | B9: Calibration-AE LV | D9: N.A. | E9: Yogurt | F9: CF
A10: AWB attr | B10: AWB attr | D10: AWB | E10: ? | F10: CF
A11: AWB info | B11: AWB info | D11: AWB | E11: CF | F11: CF
A12: AE info | B12: AE info | D12: AE | E12: Yogurt | F12: CF
A13: LSC | B13: LSC | D13: LSC | E13: CY | F13: CF
A14: DPC | B14: DPC | D14: DPC | E14: CY | F14: Kidd/Lan | H14: ?cf/alvin
A15: GE | B15: GE | D15: GE | E15: CY | F15: Kidd/Lan | G15: Crosstalk | H15: ?cf/tony green pixel imbalance
A16: HDR-Fusion | B16: HDR-Fusion | D16: WDR | E16: CY | F16: CF | G16: FSWDR
A17: HDR-DRC | B17: HDR-DRC | D17: DRC | E17: CY | F17: CF | G17: DRC
A18: NR | B18: BNR | C18: BNR | D18: BNR | E18: Alvin | F18: Kidd | G18: BNR | H18: Ready to work | K18: =COUNTIFS(BNR!$D:$D,0, BNR!$E:$E,"<>1") -> 15 | L18: =COUNTIFS(BNR!$D:$D,1, BNR!$E:$E,"<>1") -> 2 | M18: =COUNTIFS(BNR!$D:$D,9,BNR!$E:$E,"<>1") -> 0
A19: Demosaic | B19: Demosaic | C19: CFAI | D19: Demosiac | E19: Alvin | F19: Kidd | G19: Demosaic | H19: ?tony green pixel imbalance | K19: =COUNTIFS(Demosaic!$D:$D,0,Demosaic!$E:$E,"<>1") -> 22 | L19: =COUNTIFS(Demosaic!$D:$D,1,Demosaic!$E:$E,"<>1") -> 1 | M19: =COUNTIFS(Demosaic!$D:$D,9,Demosaic!$E:$E,"<>1") -> 1
A20: RGB sharpen | B20: RGB sharpen | D20: Sharpen | E20: Alvin | F20: CF
A21: Gamma | B21: Gamma | D21: Gamma | E21: Alvin | F21: CF
A22: Dehaze | B22: Dehaze | D22: Dehaze | E22: Alvin | F22: CF
A23: HSV | B23: HSV | D23: N.A. | E23: Yogurt | F23: CF | G23: Hsv
A24: 3D-LUT | B24: 3D-LUT | D24: CLUT | E24: Yogurt | F24: CF | G24: Clut
A25: 3DNR | B25: 3DNR | D25: 3DNR | E25: CY | F25: CF
A26: NR | B26: YNR | C26: YNR | D26: YNR | E26: Alvin | F26: Kidd | G26: YNR | H26: ?cf/tony | K26: =COUNTIFS(YNR!$D:$D,0,YNR!$E:$E,"<>1") -> 15 | L26: =COUNTIFS(YNR!$D:$D,1,YNR!$E:$E,"<>1") -> 10 | M26: =COUNTIFS(YNR!$D:$D,9,YNR!$E:$E,"<>1") -> 0
A27: NR | B27: CNR | C27: CNR | D27: CNR | E27: Alvin | F27: Kidd | G27: CNR | H27: ?cf | K27: =COUNTIFS(CNR!$D:$D,0,CNR!$E:$E,"<>1") -> 6 | L27: =COUNTIFS(CNR!$D:$D,1,CNR!$E:$E,"<>1") -> 10 | M27: =COUNTIFS(CNR!$D:$D,9,CNR!$E:$E,"<>1") -> 0
A28: PFC | B28: PFC | D28: CAC | E28: Alvin | F28: CF | G28: LocalCac
A29: DCI | B29: DCI | C29: DCI | D29: LDCI | E29: Alvin | F29: Kidd | G29: DCI | H29: ?alvin/cf/tony | K29: =COUNTIFS(DCI!D:D,0,DCI!$E:$E,"<>1") -> 8 | L29: =COUNTIFS(DCI!E:E,1,DCI!$E:$E,"<>1") -> 0 | M29: =COUNTIFS(DCI!F:F,9,DCI!$E:$E,"<>1") -> 0
A30: Y sharpen | B30: Y sharpen | D30: Sharpen | E30: CY | F30: CF | I30: Sharpen | J30: rgb/y
A31: FPN | B31: FPN | D31: FPN | E31: CY | F31: CF | G31: Low Priority
A32: AF | B32: AF | D32: ? | E32: CY | F32: ? | G32: Low Priority | I32: ColorTone, AWB?
A33: MeshShading | B33: MeshShading | D33: ? | E33: ? | F33: ?

Sheet _rev.
A1: vision | B1: date | C1: description
A2: 1 | B2: 43781 | C2: First revision

Sheet Hisi overview
A1: type | B1: page | C1: GUI owner | D1: MPI owner | E1: tab | F1: header | G1: MPI | H1: Note
B2: Top | D2: Jammy/Arena | E2: Mode Handle | G2: can't find | H2: Arena 負責 Venc，其餘Jammy負責
D3: Kidd/CF | E3: Bypass Setting | F3: mpi_isp.h | G3: HI_MPI_ISP_SetModuleControl()
D4: Kidd/CF | E4: Fmw State | F4: mpi_isp.h | G4: HI_MPI_ISP_SetFMWState()
D5: Kidd/CF | E5: CTRL Param | F5: mpi_isp.h | G5: HI_MPI_ISP_GetCtrlParam()
D6: Kidd/CF | E6: MOD Param | F6: mpi_isp.h | G6: HI_MPI_ISP_GetModuleControl()
D7: Jammy | E7: Repeat | F7: mpi_vi.h | G7: HI_MPI_VI_SetPipeRepeatMode()
B8: PubAttr | D8: Kidd/CF | E8: PubAttr | F8: mpi_isp.h | G8: HI_MPI_ISP_GetPubAttr()
B9: ISP Info | D9: Kidd/CF | E9: ISP Info | G9: can't find
B10: ExposureAttr | D10: Kidd/CF | E10: Exposure | F10: mpi_ae.h | G10: HI_MPI_ISP_SetExposureAttr()
E11: Exposure Auto | F11: mpi_ae.h | G11: as above
E12: Exposure Manual | F12: mpi_ae.h | G12: as above
B13: WDR ExposureAttr | D13: Kidd/CF | E13: WDR ExposureAttr | F13: mpi_ae.h | G13: HI_MPI_ISP_SetWDRExposureAttr()
B14: ExposureInfo | D14: Kidd/CF | E14: ExposureInfo | F14: mpi_ae.h | G14: HI_MPI_ISP_QueryExposureInfo()
B15: AE Route | D15: Kidd/CF | E15: AE Route | F15: mpi_ae.h | G15: HI_MPI_ISP_SetAERouteAttr()
E16: AE RouteEx | F16: mpi_ae.h | G16: HI_MPI_ISP_SetAERouteAttrEx()
B17: AutoIris | D17: Kidd/CF | E17: AIAttr | F17: mpi_ae.h | G17: HI_MPI_ISP_SetIrisAttr()
E18: DcirisAttr | F18: mpi_ae.h | G18: HI_MPI_ISP_SetDcirisAttr()
E19: PirisAttr | F19: mpi_ae.h | G19: HI_MPI_ISP_SetPirisAttr()
B20: WB Attr | D20: Kidd/CF | E20: White Balance | F20: mpi_awb.h | G20: HI_MPI_ISP_SetWBAttr()
E21: AWBAttr | G21: as above
E22: MWBAttr | G22: as above
E23: AWBAttrEx | F23: mpi_awb.h | G23: HI_MPI_ISP_SetAWBAttrEx()
E24: BlackLevel | F24: mpi_isp.h | G24: HI_MPI_ISP_SetBlackLevelAttr
B25: Spec AWB Attr | D25: Kidd/CF | E25: Spec AWB Attr | F25: mpi_awb.h | G25: HI_MPI_ISP_SetSpecAwbAttr() | H25: AI AWB, 我們還沒有
A26: chart | B26: Spec AWB | D26: Kidd/CF | E26: Spec AWB
B27: WB Info | D27: Kidd/CF | E27: WB Info | F27: mpi_awb.h | G27: HI_MPI_ISP_QueryWBInfo()
E28: CalGainByTemp
B29: CCM | D29: Kidd/CF | E29: CCM | F29: mpi_awb.h | G29: HI_MPI_ISP_SetCCMAttr()
E30: ColorToneAttr | F30: mpi_awb.h | G30: HI_MPI_ISP_SetColorToneAttr()
B31: Saturation | D31: Kidd/CF | E31: Saturation | F31: mpi_awb.h | G31: HI_MPI_ISP_SetSaturationAttr()
B32: CLUT | D32: Kidd/CF | E32: CLUT Attr | F32: mpi_isp.h | G32: HI_MPI_ISP_SetClutAttr()
E33: CLUT Lut | F33: mpi_isp.h | G33: HI_MPI_ISP_SetClutCoeff()
B34: Demosaic | D34: Kidd/CF | E34: Demosaic | F34: mpi_isp.h | G34: HI_MPI_ISP_SetDemosaicAttr()
B35: AntiFalseColor | D35: Kidd/CF | E35: AntiFalse | F35: mpi_isp.h | G35: HI_MPI_ISP_SetAntiFalseColorAttr()
B36: NR | D36: Kidd/CF | E36: Denoise | F36: mpi_isp.h | G36: HI_MPI_ISP_SetNRAttr()
E37: VPSS_3DNRAttr | F37: mpi_vpss.h | G37: HI_MPI_VPSS_GetGrpAttr()
A38: chart | B38: 3DNR X | D38: Kidd/CF | E38: 3DNR X | G38: ?
A39: chart | B39: 3DNR Curve | D39: Kidd/CF | E39: 3DNR Curve | G39: ?
A40: chart | B40: YUV Sharpen | D40: Kidd/CF | E40: YUV Sharpen | F40: mpi_isp.h | G40: HI_MPI_ISP_SetIspSharpenAttr()
...

Sheet MeshShading
A1: Function section | B1: API name | C1: API parameter | D1: UI Level | E1: Calibration | F1: low value | G1: high value | H1: default value | I1: auto | J1: register | K1: dynamic | L1: low value | M1: high value | N1: default value | O1: description
A2: mesh lsc common | C2: lsc_enable | F2: 0 | G2: 1 | H2: 0 | I2: 0 | J2: reg_lsc_enable | K2: 0 | L2: 0 | M2: 1 | N2: 0 | O2: Enable LSC
C3: lsc_strength | F3: 0 | G3: 4095 | H3: 4095 | I3: 1 | J3: reg_lsc_strength | K3: 1 | L3: 0 | M3: 4095 | N3: 4095 | O3: global strength of LSC
C4: lsc_debug | F4: 0 | G4: 1 | H4: 0 | I4: 0 | J4: reg_lsc_debug | K4: 0 | L4: 0 | M4: 1 | N4: 0 | O4: Rsvd
A5: meh lsc configure | C5: lsc_xblknumm1 | F5: 0 | G5: 63 | H5: 37 | I5: 0 | J5: reg_lsc_xblknumm1 | K5: 0 | L5: 0 | M5: 63 | N5: 37 | O5: RSVD
C6: reg_lsc_yblknumm1 | F6: 0 | G6: 63 | H6: 37 | I6: 0 | J6: reg_lsc_yblknumm1 | K6: 0 | L6: 0 | M6: 63 | N6: 37 | O6: RSVD
C7: reg_lsc_xstep | F7: 0 | G7: 32767 | H7: 0 | I7: 0 | J7: reg_lsc_xstep | K7: 0 | L7: 0 | M7: 32767 | N7: 0 | O7: ratio of block number over image size -- X
C8: reg_lsc_ystep | F8: 0 | G8: 32767 | H8: 0 | I8: 0 | J8: reg_lsc_ystep | K8: 0 | L8: 0 | M8: 32767 | N8: 0 | O8: ratio of block number over image size -- Y
C9: reg_lsc_imgx0 | F9: 0 | G9: 4194303 | H9: 0 | I9: 0 | J9: reg_lsc_imgx0 | K9: 0 | L9: 0 | M9: 4194303 | N9: 0 | O9: X start position in mesh domain
C10: reg_lsc_imgy0 | F10: 0 | G10: 4194303 | H10: 0 | I10: 0 | J10: reg_lsc_imgy0 | K10: 0 | L10: 0 | M10: 4194303 | N10: 0 | O10: Y start position in mesh domain
C11: reg_lsc_gain_base | F11: 0 | G11: 3 | H11: 0 | I11: 0 | J11: reg_lsc_gain_base | K11: 0 | L11: 0 | M11: 3 | N11: 0 | O11: gain
A12: mesh lsc table | C12: reg_lsc_rtbl[1369] | F12: 0 | G12: 4095 | H12: 512 | I12: 1 | J12: reg_lsc_rtbl[1369] | K12: 1 | L12: 0 | M12: 4095 | N12: 512 | O12: 1x=512
C13: reg_lsc_gtbl[1369] | F13: 0 | G13: 4095 | H13: 512 | I13: 1 | J13: reg_lsc_gtbl[1369] | K13: 1 | L13: 0 | M13: 4095 | N13: 512 | O13: 1x=512
C14: reg_lsc_btbl[1369] | F14: 0 | G14: 4095 | H14: 512 | I14: 1 | J14: reg_lsc_btbl[1369] | K14: 1 | L14: 0 | M14: 4095 | N14: 512 | O14: 1x=512
A15: mesh scaler | C15: reg_lsc_scaler[256] | F15: 0 | G15: 4095 | I15: 0 | J15: reg_lsc_scaler[256] | K15: 0 | L15: 0 | M15: 4095
A16: radius lsc common | C16: lscr_enable | F16: 0 | G16: 1 | H16: 0 | I16: 0 | J16: reg_lscr_enable | K16: 0 | L16: 0 | M16: 1 | N16: 0 | O16: Enable radius LSC
C17: lscr_strnth | F17: 0 | G17: 4095 | H17: 0 | I17: 1 | J17: reg_lscr_strnth | K17: 1 | L17: 0 | M17: 4095 | N17: 0 | O17: x coordinate of lens center
A18: radius lsc configure | C18: lscr_centerx | F18: 0 | G18: 4095 | H18: 0 | I18: 0 | J18: reg_lscr_centerx | K18: 0 | L18: 0 | M18: 4095 | N18: 0 | O18: y coordinate of lens center
C19: lscr_centery | F19: 0 | G19: 2047 | H19: 0 | I19: 0 | J19: reg_lscr_centery | K19: 0 | L19: 0 | M19: 2047 | N19: 0 | O19: normalized factor
C20: lscr_norm | F20: 0 | G20: 32767 | H20: 0 | I20: 0 | J20: reg_lscr_norm | K20: 0 | L20: 0 | M20: 32767 | N20: 0 | O20: lens shading correction strength
A21: radius lsc table | C21: lscr_gain_lut[32] | F21: 0 | G21: 4095 | H21: 512 | I21: 1 | J21: reg_lscr_gain_lut[32] | K21: 1 | L21: 0 | M21: 4095 | N21: 512 | O21: radius gain table

Sheet Dehaze
A1: Function section | B1: API name | C1: API parameter | D1: UI Level | E1: Calibration | F1: low value | G1: high value | H1: default value | I1: parameter description | J1: auto | K1: register | L1: dynamic | M1: low value | N1: high value | O1: default value | P1: description
A2: Common | B2: BM_MPI_ISP_SetDehazeAttr | C2: Enable | D2: 0 | F2: 0 | G2: 1 | H2: 0 | I2: Dehaze功能使能。_x000D_ 0: 關閉。_x000D_ 1: 始能。_x000D_ | J2: 0 | K2: reg_dehaze_enable | L2: 1 | M2: 0 | N2: 1 | O2: 0 | P2: Dehaze enable
C3: Strength | D3: 0 | F3: 0 | G3: 100 | H3: 60 | I3: 用來控制Dehaze的強度。值越大，去霧強度越強。 | J3: 1 | K3: reg_dehaze_w | L3: 1 | M3: 0 | N3: 100 | O3: 60 | P3: Strength of dehaze
C4: CumulativeThr | D4: 0 | F4: 0 | G4: 16383 | H4: 512 | I4: 計算霧濃度的統計閾值。 | J4: 1 | K4: reg_dehaze_cum_th | L4: 1 | M4: 0 | N4: 16383 | O4: 512 | P4: Cumulative threshold
C5: HistThr | D5: 0 | F5: 0 | G5: 16383 | H5: 1024 | I5: 計算大氣光的統計閾值。 | J5: 1 | K5: reg_dehaze_hist_th | L5: 1 | M5: 0 | N5: 16383 | O5: 1024 | P5: Histogram threshold
C6: MinTransMapValue | D6: 1 | F6: 0 | G6: 8191 | H6: 819 | I6: 透射係數允許之最小值。 | J6: 1 | K6: reg_dehaze_tmap_min | L6: 1 | M6: 0 | N6: 8191 | O6: 819 | P6: Mininum transmission map value allowed
C7: MaxTransMapValue | D7: 1 | F7: 0 | G7: 8191 | H7: 8191 | I7: 透射係數允許之最大值。 | J7: 1 | K7: reg_dehaze_tmap_max | L7: 1 | M7: 0 | N7: 8191 | O7: 8191 | P7: Maximum transmission value allowed
C8: VarThr | D8: 1 | F8: 0 | G8: 1023 | H8: 200 | I8: 用來邊緣偵測的閾值。 | J8: 1 | K8: reg_dehaze_th_smooth | L8: 1 | M8: 0 | N8: 1023 | O8: 200 | P8: Threshold for edge classification
A11: API parameter 藍色標記的參數: 代表預設顯示在UI上。
A12: API parameter 黑色標記的參數: 代表預設不顯示在UI，開啟工程模式才會在UI上顯示。

Sheet CAC
A1: Function section | B1: API name | C1: API parameter | D1: UI Level | E1: Calibration | F1: low value | G1: high value | H1: default value | I1: parameter description | J1: auto | K1: register | L1: dynamic | M1: low value | N1: high value | O1: default value | P1: description
A2: Common | B2: BM_MPI_ISP_SetLocalCacAttr | C2: Enable | D2: 0 | F2: 0 | G2: 1 | H2: 0 | I2: CAC模塊使能。_x000D_ 0: 關閉。_x000D_ 1: 使能。_x000D_ | J2: 0 | K2: reg_pfc_enable | L2: 1 | M2: 0 | N2: 1 | O2: 0 | P2: CAC enable
C3: VarThr | D3: 0 | F3: 0 | G3: 511 | H3: 256 | I3: 邊緣偵測的閾值。值越小，越多區域被判斷為邊緣。 | J3: 1 | K3: reg_cnr_var_th | L3: 1 | M3: 0 | N3: 511 | O3: 256 | P3: Edge detection threshold
C4: PurpleDetRange | D4: 0 | F4: 0 | G4: 128 | H4: 45 | I4: 紫邊偵測的閾值。值越大，越多區域被判斷為紫邊。 | J4: 1 | K4: reg_cnr_purple_th | L4: 1 | M4: 0 | N4: 128 | O4: 45 | P4: Purple fring detection scope
C5: DePurpleStr | D5: 0 | F5: 0 | G5: 255 | H5: 128 | I5: 去紫邊強度。值越大，紫邊現象越少。 | J5: 1 | K5: reg_cnr_correct_strength | L5: 1 | M5: 0 | N5: 255 | O5: 128 | P5: Strenght of purple fringe correction
C6: PurpleCb | D6: 0 | F6: 0 | G6: 255 | H6: 232 | I6: 紫色在Cb domain的座標。 | J6: 1 | K6: reg_cnr_purple_cb | L6: 1 | M6: 0 | N6: 255 | O6: 232 | P6: Purple in Cb value
C7: PurpleCr | D7: 0 | F7: 0 | G7: 255 | H7: 177 | I7: 紫色在Cr domain的座標。 | J7: 1 | K7: reg_cnr_purple_cr | L7: 1 | M7: 0 | N7: 255 | O7: 177 | P7: Purple in Cr value
C8: GreenCb | D8: 0 | F8: 0 | G8: 255 | H8: 43 | I8: 綠色在Cb domain的座標。 | J8: 1 | K8: reg_cnr_green_cb | L8: 1 | M8: 0 | N8: 255 | O8: 43 | P8: Green in Cb value
C9: GreenCr | D9: 0 | F9: 0 | G9: 255 | H9: 21 | I9: 綠色在Cr domain的座標。 | J9: 1 | K9: reg_cnr_green_cr | L9: 1 | M9: 0 | N9: 255 | O9: 21 | P9: Green in Cr value
C10: TuningMode | D10: 0 | F10: 0 | G10: 2 | H10: 0 | I10: 輸出中繼檔案，輔助調節參數。_x000D_ 0: CAC圖像結果。_x000D_ 1: 邊緣偵測圖像結果。_x000D_ 2: 紫邊偵測圖像結果。_x000D_ | J10: 0 | K10: reg_cnr_out_sel | L10: 1 | M10: 0 | N10: 2 | O10: 0 | P10: Tuning mode
A13: API parameter 藍色標記的參數: 代表預設顯示在UI上。
A14: API parameter 黑色標記的參數: 代表預設不顯示在UI，開啟工程模式才會在UI上顯示。

Sheet Gamma
A1: Function section | B1: API name | C1: API parameter | D1: UI Level | E1: Calibration | F1: low value | G1: high value | H1: default value | I1: parameter description | J1: auto | K1: register | L1: dynamic | M1: low value | N1: high value | O1: default value | P1: description
A2: Common | B2: CVI_MPI_ISP_SetGammaAttr | C2: Enable | D2: 0 | F2: 0 | G2: 1 | H2: 0 | I2: Gamma功能使能。_x000D_ 0: 關閉。_x000D_ 1: 始能。_x000D_ | J2: 0 | K2: reg_gamma_enable | L2: 1 | M2: 0 | N2: 1 | O2: 0 | P2: Gamma enable
C3: Table[256] | J3: 0 | K3: reg_g_gamma[256] | L3: 1 | M3: 0 | N3: 4095 | O3: 0 | P3: Gamma LUT
A7: API parameter 藍色標記的參數: 代表預設顯示在UI上。
A8: API parameter 黑色標記的參數: 代表預設不顯示在UI，開啟工程模式才會在UI上顯示。

Sheet DCI
A1: Function section | B1: API name | C1: API parameter | D1: UI Level | E1: Calibration | F1: low value | G1: high value | H1: default value | I1: parameter description | J1: auto | K1: register | L1: dynamic | M1: low value | N1: high value | O1: default value | P1: description | Q1: isp_param_def.h | R1: dvi_vip_tun_cfg.h | S1: ISP_API | T1: Note
A2: Common | B2: CVI_MPI_ISP_SetLDCIAttr | C2: Enable | D2: 0 | F2: 0 | G2: 1 | H2: 0 | I2: DCI模塊使能。 0: 關閉。 1: 使能。 | J2: 0 | K2: reg_dci_enable | L2: 1 | M2: 0 | N2: 1 | O2: 0 | P2: DCI enable | Q2: ISP_DCI_ENABLE | R2: enable | T2: ISP_DCI_ENOPTYPE
C3: MapEnable | D3: 0 | F3: 0 | G3: 1 | H3: 1 | I3: DCI mapping功能使能。 0: 關閉。 1: 使能。 | J3: 1 | K3: reg_dci_map_enable | L3: 1 | M3: 0 | N3: 1 | O3: 1 | P3: DCI mapping enable
C4: DitherEnable | D4: 9 | F4: 0 | G4: 1 | H4: 1 | I4: Dither功能使能。 0: 關閉。_x000D_ 1: 始能。 | J4: 1 | K4: reg_dci_dither_enable | L4: 1 | M4: 0 | N4: 1 | O4: 1 | P4: Enable of dither | Q4: ISP_DCI_MANUAL_DITHERENABLE | R4: dither_enable | T4: always 1
C5: RoiEnable | D5: 9 | F5: 0 | G5: 1 | H5: 0 | I5: ROI裁剪功能使能。 0: 關閉。 1: 始能。 | J5: 1 | K5: reg_dci_roi_enable | L5: 1 | M5: 0 | N5: 1 | O5: 0 | P5: ROI enable
C6: RoiStartX | D6: 9 | F6: 0 | G6: 4095 | H6: 0 | I6: 定義 ROI 左上角的 X 座標。 | J6: 1 | K6: reg_dci_roi_start_x | L6: 1 | M6: 0 | N6: 4095 | O6: 0 | P6: ROI X coordinate
C7: RoiStartY | D7: 9 | F7: 0 | G7: 2159 | H7: 0 | I7: 定義 ROI 左上角的 Y 座標。 | J7: 1 | K7: reg_dci_roi_start_y | L7: 1 | M7: 0 | N7: 2159 | O7: 0 | P7: ROI Y coordinate
C8: RoiWidth | D8: 9 | F8: 0 | G8: 4095 | H8: 0 | I8: 定義 ROI 的寬度。 | J8: 1 | K8: reg_dci_roi_widthm1 | L8: 1 | M8: 0 | N8: 4095 | O8: 0 | P8: ROI width
C9: RoiHeight | D9: 9 | F9: 0 | G9: 2159 | H9: 0 | I9: 定義 ROI 的高度。 | J9: 1 | K9: reg_dci_roi_heightm1 | L9: 1 | M9: 0 | N9: 2159 | O9: 0 | P9: ROI height
C10: TuningMode | D10: 0 | F10: 0 | G10: 1 | H10: 1 | I10: 在同一畫面同時顯示原始圖像和結果圖像，輔助調節參數。_x000D_ 0: CAC圖像結果。_x000D_ 1: 在同一畫面同時顯示原始圖像和結果圖像。 _x000D_ | J10: 0 | K10: reg_dci_demo_mode | L10: 1 | M10: 0 | N10: 0 | O10: 0 | P10: Tuning mode | Q10: ISP_DCI_MANUAL_TUNINGMODE | R10: demo_mode
C11: DelayFrmNum | D11: 9 | F11: 0 | G11: 2048 | H11: 0 | I11: 延遲的帧數。 | K11: algo_dci_history_nframes | L11: 1 | M11: 0 | N11: 2048 | O11: 0 | P11: Number of frames to delay
C12: ContrastGain | D12: 0 | F12: 0 | G12: 1023 | H12: 100 | I12: 用來控制DCI的強度，值越大，對比度越大。 | J12: 1 | K12: algo_dci_cliplimit_sel | L12: 1 | M12: 0 | N12: 1023 | O12: 100 | P12: Strength of DCI | Q12: ISP_DCI_MANUAL_CONTRASTGAIN | R12: N/A
C13: BlcThr | D13: 0 | F13: 0 | G13: 255 | H13: 60 | I13: 用來決定暗區範圍的門檻值。值越大，包含的暗區範圍越大。 | J13: 1 | K13: algo_dci_bw_strecth_th_0 | L13: 1 | M13: 0 | N13: 255 | O13: 60 | P13: Black stretching threshold | Q13: ISP_DCI_MANUAL_BLCTHR | R13: N/A
C14: WhtThr | D14: 0 | F14: 0 | G14: 255 | H14: 200 | I14: 用來決定亮區範圍的門檻值。值越小，包含的亮區範圍越大。 | J14: 1 | K14: algo_dci_bw_strecth_th_1 | L14: 1 | M14: 0 | N14: 255 | O14: 200 | P14: White stretching threshold | Q14: ISP_DCI_MANUAL_WHTTHR | R14: N/A
C15: BlcCtrl | D15: 0 | F15: 0 | G15: 512 | H15: 256 | I15: 用來決定暗區的對比度。以256為中心，值越大，對比度越大；值越小，對比度越小。 | J15: 1 | K15: algo_dci_bw_strecth_strength_0 | L15: 1 | M15: 0 | N15: 512 | O15: 256 | P15: Black stretching strength | Q15: ISP_DCI_MANUAL_BLCCTRL | R15: N/A
C16: WhtCtrl | D16: 0 | F16: 0 | G16: 512 | H16: 256 | I16: 用來決定亮區的對比度。以256為中心，值越大，對比度越大；值越小，對比度越小。 | J16: 1 | K16: algo_dci_bw_strecth_strength_1 | L16: 1 | M16: 0 | N16: 512 | O16: 256 | P16: White stretching strength | Q16: ISP_DCI_MANUAL_WHTCTRL | R16: N/A
K17: reg_dci_map_lut[256] | P17: DCI mapping LUT | Q17: ? | R17: __u16 *map_lut | T17: alvin will provide mapping function
K18: ? | P18: ? | Q18: ? | R18: ? | T18: //@TODO alvin will add some register
A20: API parameter 藍色標記的參數: 代表預設顯示在UI上。
A21: API parameter 黑色標記的參數: 代表預設不顯示在UI，開啟工程模式才會在UI上顯示。

Sheet Demosaic
A1: Function section | B1: API name | C1: API parameter | D1: UI Level | E1: Calibration | F1: low value | G1: high value | H1: default value | I1: parameter description | J1: auto | K1: register | L1: dynamic | M1: low value | N1: high value | O1: default value | P1: description | Q1: isp_param_def.h | R1: cvi_vip_tun_cfg.h | S1: ISP_API | T1: Note
A2: Common | B2: CVI_MPI_ISP_SetDemosaicAttr | C2: Enable | D2: 0 | F2: 0 | G2: 1 | H2: 0 | I2: Demosaic模塊使能。 0: 關閉。 1: 始能。 | J2: 0 | K2: reg_cfa_enable | L2: 1 | M2: 0 | N2: 1 | O2: 0 | P2: Demosaic enable | Q2: ISP_DEMOSAIC_ENABLE | R2: cfa_enable | T2: ISP_DEMOSAIC_ENOPTYPE
C3: CoarseEdgeThr | D3: 0 | F3: 0 | G3: 4095 | H3: 480 | I3: 邊緣粗調偵測閾值。值越小，偵測為邊緣的數量越多。建議搭配參數CoarseStr調試。 | J3: 1 | K3: reg_cfa_edgee_thd | L3: 1 | M3: 0 | N3: 4095 | O3: 480 | P3: Threshold for coarse edge detection | Q3: ISP_DEMOSAIC_MANUAL_COARSEEDGETHR | R3: demosiac_cfg.REG_3
C4: CoarseStr | D4: 0 | F4: 0 | G4: 4095 | H4: 128 | I4: 邊緣粗調插值強度。值越小，紋理細節越多。 | J4: 1 | K4: reg_cfa_edge_tol | L4: 1 | M4: 0 | N4: 4095 | O4: 128 | P4: Threshold for coarse edge direction determination | Q4: ISP_DEMOSAIC_MANUAL_COARSESTR | R4: demosiac_cfg.REG_4_1
C5: FineEdgeThr | D5: 0 | F5: 0 | G5: 4095 | H5: 400 | I5: 邊緣細調偵測閾值。值越小，偵測為邊緣的數量越多。建議搭配參數FineStr調試。 | J5: 1 | K5: reg_cfa_sige_thd | L5: 1 | M5: 0 | N5: 4095 | O5: 400 | P5: Threshold for fine edge detection | Q5: ISP_DEMOSAIC_MANUAL_FINEEDGETHR | R5: demosiac_cfg.REG_3
C6: FineStr | D6: 0 | F6: 0 | G6: 4095 | H6: 40 | I6: 邊緣細調插值強度。值越小，偵測為邊緣的數量越多。 | J6: 1 | K6: reg_cfa_gsig_tol | L6: 1 | M6: 0 | N6: 4095 | O6: 40 | P6: Threhosld for G channel fine edge direction determination | Q6: ISP_DEMOSAIC_MANUAL_FINESTR | R6: demosiac_cfg.REG_4
K7: reg_cfa_rbsig_tol | L7: 1 | M7: 0 | N7: 4095 | O7: 40 | P7: Threhosld for R/B channel fine edge direction determination | Q7: ISP_DEMOSAIC_MANUAL_FINESTR | R7: demosiac_cfg.REG_4 | T7: as above
C8: TuningMode | I8: 輸出中繼檔案，輔助調節參數。 0: Demosaic圖像結果。 1: 平坦/垂直/水平邊緣偵測圖像結果。 | J8: 0 | K8: reg_cfa_out_sel | M8: 0 | N8: 1 | O8: 0 | P8: Tuning mode
C9: AdaThr | D9: 0 | F9: 0 | G9: 4095 | H9: 3580 | I9: 自適應高頻插值閾值。值越大，高頻細節保留越多。 | J9: 1 | K9: reg_cfa_ghp_thd | L9: 1 | M9: 0 | N9: 4095 | O9: 3584 | P9: Threshold for edge-adaptive interpolation | Q9: ISP_DEMOSAIC_MANUAL_ADAPSTR | R9: demosiac_cfg.REG_5
C10: Table[32] | D10: 9 | F10: 0 | G10: 31 | H10: {8, 8, 8, 8, 10, 10, 10, 10, 12, 12, 12, 12, 14, 14, 14, 14, 16, 16, 16, 16, 20, 20, 20, 20, 24, 24, 24, 24, 28, 28, 31, 31} | J10: 0 | K10: reg_cfa_ghp_lut00 ~ reg_cfa_ghp_lut31 | L10: 1 | M10: 0 | N10: 31 | Q10: ISP_DEMOSAIC_TABLE_[32] | R10: __u8 *cfa_ghp_lut | T10: use default value
A11: DeMoire | B11: CVI_MPI_ISP_SetDemosaicDemoireAttr | C11: DetailSmoothEnable | D11: 0 | F11: 0 | G11: 1 | H11: 0 | I11: 細節平滑功能使能。_x000D_ 0: 關閉。_x000D_ 1: 使能。_x000D_ | J11: 1 | K11: reg_cfa_moire_enable | L11: 1 | M11: 0 | N11: 1 | O11: 0 | P11: Detail smooth enable | Q11: ISP_DEMOSAIC_MANUAL_DEMOIREENABLE | R11: __u8 cfa_moire_enable
C12: DetailSmoothStr | D12: 0 | F12: 0 | G12: 255 | H12: 0 | I12: 細節平滑強度。值越大，平滑強度越強，對偽細節的抑制強度越大。 | J12: 1 | K12: reg_cfa_moire_strth | L12: 1 | M12: 0 | N12: 255 | O12: 0 | P12: Detail smooth strength | Q12: ISP_DEMOSAIC_MANUAL_DEMOIRESTR | R12: demosiac_1_cfg.REG_10
C13: EdgeWgtStr | D13: 1 | F13: 0 | G13: 255 | H13: 255 | I13: 自適應性方向細節平滑強度。值越小，平滑強度越強。 | J13: 1 | K13: reg_cfa_moire_wght_gain | L13: 1 | M13: 0 | N13: 255 | O13: 255 | P13: Edge-adaptive detail smooth strength | Q13: ISP_DEMOSAIC_MANUAL_EDGEWGTSTR | R13: demosiac_1_cfg.REG_10
A14: Filter | B14: CVI_MPI_ISP_SetDemosaicFilterAttr | C14: NpThr | D14: 9 | E14: 1 | F14: 0 | G14: 4095 | H14: 0 | I14: Noise profile 的亮度閾值。 | J14: 1 | K14: reg_cfa_moire_np_ymin | L14: 1 | M14: 0 | N14: 4095 | O14: 0 | P14: Noise profile threshold | Q14: ISP_DEMOSAIC_MANUAL_NPTHRLUMA | R14: demosiac_1_cfg.REG_11
C15: NpSlope | D15: 9 | E15: 1 | F15: 0 | G15: 255 | H15: 0 | I15: Noise profile 的斜率。 | J15: 1 | K15: reg_cfa_moire_np_yslope | L15: 1 | M15: 0 | N15: 255 | O15: 0 | P15: Noise profile slope | Q15: ISP_DEMOSAIC_MANUAL_NPSLOPELUMA | R15: demosiac_1_cfg.REG_10
C16: NpLowOffset | D16: 9 | E16: 1 | F16: 0 | G16: 255 | H16: 0 | I16: Noise profile 可允許的最小 noise level。 | J16: 1 | K16: reg_cfa_moire_np_low | L16: 1 | M16: 0 | N16: 255 | O16: 0 | P16: Noise profile low offset | Q16: ISP_DEMOSAIC_MANUAL_NPLOWOFFSETLUMA | R16: demosiac_1_cfg.REG_11
C17: NpHighOffset | D17: 9 | E17: 1 | F17: 0 | G17: 255 | H17: 0 | I17: Noise profile 可允許的最大 noise level。 | J17: 1 | K17: reg_cfa_moire_np_high | L17: 1 | M17: 0 | N17: 255 | O17: 0 | P17: Noise profile high offset | Q17: ISP_DEMOSAIC_MANUAL_NPHIGHOFFSETLUMA | R17: demosiac_1_cfg.REG_11
C18: DetailWgtThr | D18: 0 | F18: 0 | G18: 4095 | H18: 512 | I18: 邊緣細節平滑保留範圍閾值。值越小，細節保留越多。 | J18: 1 | K18: reg_cfa_moire_diffthd_min | L18: 1 | M18: 0 | N18: 4095 | O18: 512 | P18: Diff profile threshold | Q18: ISP_DEMOSAIC_MANUAL_DIFFTHR | R18: demosiac_1_cfg.REG_12
F19: 0 | G19: 4095 | H19: 512 | J19: 1 | K19: reg_cfa_moire_sadthd_min | L19: 1 | M19: 0 | N19: 4095 | O19: 512 | P19: SAD profile threshold | Q19: ISP_DEMOSAIC_MANUAL_DIFFTHR | R19: demosiac_1_cfg.REG_13 | T19: as above
C20: DetailWgtSlope | D20: 0 | F20: 0 | G20: 255 | H20: 64 | I20: 邊緣細節平滑邊緣保留強度。值越大，細節保留所佔比重越大。 | J20: 1 | K20: reg_cfa_moire_diffthd_slope | L20: 1 | M20: 0 | N20: 255 | O20: 64 | P20: Diff profile slope | Q20: ISP_DEMOSAIC_MANUAL_DIFFSLOPE | R20: demosiac_1_cfg.REG_12
G21: 255 | H21: 64 | J21: 1 | K21: reg_cfa_moire_sadthd_slope | L21: 1 | M21: 0 | N21: 255 | O21: 64 | P21: SAD profile slope | Q21: ISP_DEMOSAIC_MANUAL_DIFFSLOPE | R21: demosiac_1_cfg.REG_14 | T21: as above
C22: DetailWgtMin | D22: 0 | F22: 0 | G22: 255 | H22: 0 | I22: 邊緣細節平滑保留允許之最小強度。 | J22: 1 | K22: reg_cfa_moire_diffw_low | L22: 1 | M22: 0 | N22: 255 | O22: 0 | P22: Diff profile low offset | Q22: ISP_DEMOSAIC_MANUAL_DIFFLOWOFFSET | R22: demosiac_1_cfg.REG_13
G23: 255 | H23: 0 | J23: 1 | K23: reg_cfa_moire_sadw_low | L23: 1 | M23: 0 | N23: 255 | O23: 0 | P23: SAD profile low offset | Q23: ISP_DEMOSAIC_MANUAL_DIFFLOWOFFSET | R23: demosiac_1_cfg.REG_14 | T23: as above
C24: DetailWgtMax | D24: 0 | F24: 0 | G24: 255 | H24: 255 | I24: 邊緣細節平滑保留允許之最大強度。 | J24: 1 | K24: reg_cfa_moire_diffw_high | L24: 1 | M24: 0 | N24: 255 | O24: 255 | P24: Diff profile high offset | Q24: ISP_DEMOSAIC_MANUAL_DIFFHIGHOFFSET | R24: demosiac_1_cfg.REG_13
F25: 0 | G25: 255 | H25: 255 | J25: 1 | K25: reg_cfa_moire_sadw_high | L25: 1 | M25: 0 | N25: 255 | O25: 255 | P25: SAD profile high offset | Q25: ISP_DEMOSAIC_MANUAL_DIFFHIGHOFFSET | R25: demosiac_1_cfg.REG_14 | T25: as above
C26: LumaWgtThr | D26: 0 | F26: 0 | G26: 4095 | H26: 256 | I26: 亮度細節平滑作用範圍閾值。值越小，細節平滑作用的範圍越大。 | J26: 1 | K26: reg_cfa_moire_lumathd_min | L26: 1 | M26: 0 | N26: 4095 | O26: 256 | P26: Luma profile threshold | Q26: ISP_DEMOSAIC_MANUAL_LUMATHRMIN | R26: demosiac_1_cfg.REG_16
C27: LumaWgtSlope | D27: 0 | F27: 0 | G27: 255 | H27: 96 | I27: 亮度細節平滑邊緣保留強度。值越大，細節平滑強度越強。 | J27: 1 | K27: reg_cfa_moire_lumathd_slope | L27: 1 | M27: 0 | N27: 255 | O27: 96 | P27: Luma profile slope | Q27: ISP_DEMOSAIC_MANUAL_LUMATHRSLOPE | R27: demosiac_1_cfg.REG_16
C28: LumaWgtMin | D28: 0 | F28: 0 | G28: 255 | H28: 0 | I28: 亮度細節平滑強度允許之最小強度。 | J28: 1 | K28: reg_cfa_moire_lumaw_low | L28: 1 | M28: 0 | N28: 255 | O28: 0 | P28: Luma profile low offset | Q28: ISP_DEMOSAIC_MANUAL_LUMAWLOW | R28: demosiac_1_cfg.REG_15
C29: LumaWgtMax | D29: 0 | F29: 0 | G29: 255 | H29: 255 | I29: 亮度細節平滑強度允許之最大強度。 | J29: 1 | K29: reg_cfa_moire_lumaw_high | L29: 1 | M29: 0 | N29: 255 | O29: 255 | P29: Luma profile high offset | Q29: ISP_DEMOSAIC_MANUAL_LUMAWHIGH | R29: demosiac_1_cfg.REG_15
A30: EE | B30: CVI_MPI_ISP_SetDemosaicEEAttr | C30: EdgeEnhanceEnable | D30: 0 | F30: 0 | G30: 1 | H30: 1 | I30: 邊緣強化功能使能。 | J30: 1 | K30: reg_rgbee_enable | L30: 1 | M30: 0 | N30: 1 | O30: 1 | P30: Enable EE | Q30: ISP_DEMOSAIC_MANUAL_EDGEENHANCEENABLE | R30: __u8 rgbee_enable
C31: OverShtGain | D31: 0 | F31: 0 | G31: 1023 | H31: 100 | I31: 調節overshoot程度。值越大，邊緣強化越大。 | J31: 1 | K31: reg_rgbee_osgain | L31: 1 | M31: 0 | N31: 1023 | O31: 358 | P31: Overshoot gain | Q31: ISP_DEMOSAIC_MANUAL_OVERSHTGAIN | R31: __u16 rgbee_osgain
C32: UnderShtGain | D32: 0 | F32: 0 | G32: 1023 | H32: 100 | I32: 調節undershoot程度。值越大，邊緣強化越大。 | J32: 1 | K32: reg_rgbee_usgain | L32: 1 | M32: 0 | N32: 1023 | O32: 310 | P32: Undershoot gain | Q32: ISP_DEMOSAIC_MANUAL_UNDERSHTGAIN | R32: __u16 rgbee_usgain
C33: AcGainTable[33] | D33: 0 | F33: 0 | G33: 255 | H33: {0, 0, 0, 0, 0, 0, 0, 0, 0, 0, 0, 0, 0, 0, 0, 0, 0, 0, 0, 0, 0, 0, 0, 0, 0, 0, 0, 0, 0, 0, 0, 0, 0} | J33: 1 | K33: reg_rgbee_ac_lut00 ~ reg_rgbee_ac_lut32 | L33: 1 | M33: 0 | N33: 255 | O33: {0, 0, 0, 0, 0, 0, 0, 0, 0, 0, 0, 0, 0, 0, 0, 0, 0, 0, 0, 0, 0, 0, 0, 0, 0, 0, 0, 0, 0, 0, 0, 0, 0} | P33: AC gain table for edge enhancement | Q33: ISP_DEMOSAIC_MANUAL_ACGAINTABLE_[33] | R33: __u8 *rgbee_ac_lut
C34: HfGainTable[33] | D34: 0 | F34: 0 | G34: 255 | H34: {32, 32, 32, 30, 30, 30, 28, 28, 28, 28, 28, 28, 28, 28, 28, 28, 28, 28, 28, 28, 28, 28, 28, 28, 28, 28, 28, 28, 28, 28, 28, 28, 24} | J34: 1 | K34: reg_rgbee_edge_lut00 ~ reg_rgbee_edge_lut32 | L34: 1 | M34: 0 | N34: 255 | O34: {32, 32, 32, 30, 30, 30, 28, 28, 28, 28, 28, 28, 28, 28, 28, 28, 28, 28, 28, 28, 28, 28, 28, 28, 28, 28, 28, 28, 28, 28, 28, 28, 24} | P34: HF gain table for edge enhancement | Q34: ISP_DEMOSAIC_MANUAL_HFGAINTABLE_[33] | R34: __u8 *rgbee_edge_lut
C35: NpTable[33] | D35: 0 | F35: 0 | G35: 4095 | H35: {12, 16, 20, 24, 28, 28, 28, 28, 28, 28, 28, 28, 32, 32, 32, 32, 32, 32, 32, 32, 32, 32, 32, 32, 32, 32, 32, 32, 32, 32, 32, 32, 32} | J35: 1 | K35: reg_rgbee_np_lut00 ~ reg_rgbee_np_lut32 | L35: 1 | M35: 0 | N35: 4095 | O35: {12, 16, 20, 24, 28, 28, 28, 28, 28, 28, 28, 28, 32, 32, 32, 32, 32, 32, 32, 32, 32, 32, 32, 32, 32, 32, 32, 32, 32, 32, 32, 32, 32} | P35: Noise profile offset for edge enhancement | Q35: ISP_DEMOSAIC_MANUAL_NPTABLE_[33] | R35: __u16 *rgbee_np_lut
A38: API parameter 藍色標記的參數: 代表預設顯示在UI上。
A39: API parameter 黑色標記的參數: 代表預設不顯示在UI，開啟工程模式才會在UI上顯示。

Sheet DPC
A1: function section | B1: API name | C1: API parameter | D1: UI Level | E1: Calibration | F1: low value | G1: high value | H1: default value | I1: auto | J1: register | K1: dynamic | L1: low value | M1: high value | N1: default value | O1: description | P1: Autogen | Q1: isp_param_def.h | R1: Manual | S1: Auto | T1: cvi_vip_tun_cfg.h | U1: Note
A2: Common | B2: BM_MPI_ISP_SetDPDynamicAttr | C2: dpc_enable | D2: 0 | F2: 0 | G2: 1 | H2: 0 | I2: 1 | J2: reg_dpc_enable | K2: 0 | L2: 0 | M2: 1 | N2: 0 | O2: enable DPC | R2: ISP_DPC_MANUAL_DPC_ENABLE | S2: ISP_DPC_AUTO_DPC_ENABLE | U2: ISP_DPC_ENOPTYPE
C3: dpc_staticdpc_enable | D3: 0 | F3: 0 | G3: 1 | H3: 0 | I3: 1 | J3: reg_dpc_staticdpc_enable | K3: 0 | L3: 0 | M3: 1 | N3: 0 | O3: enable static DPC | R3: ISP_DPC_MANUAL_DPC_STATICDPC_ENABLE | S3: ISP_DPC_AUTO_DPC_STATICDPC_ENABLE
C4: dpc_cluster_size | D4: 0 | F4: 0 | G4: 3 | H4: 2 | I4: 1 | J4: reg_dpc_cluster_size | K4: 0 | L4: 0 | M4: 3 | N4: 2 | O4: cluster size | R4: ISP_DPC_MANUAL_DPC_CLUSTER_SIZE | S4: ISP_DPC_AUTO_DPC_CLUSTER_SIZE
A5: DPC bright strength | C5: dpc_r_bright_pixel_ratio | D5: 0 | F5: 0 | G5: 1023 | H5: 280 | I5: 1 | J5: reg_dpc_r_bright_pixel_ratio | K5: 0 | L5: 0 | M5: 1023 | N5: 280 | O5: threshold of R bright pixel , the ratio of 3/4 Avg , base is 256 | R5: ISP_DPC_MANUAL_DPC_R_BRIGHT_PIXEL_RATIO | S5: ISP_DPC_AUTO_DPC_R_BRIGHT_PIXEL_RATIO
C6: dpc_g_bright_pixel_ratio | D6: 0 | F6: 0 | G6: 1023 | H6: 280 | I6: 1 | J6: reg_dpc_g_bright_pixel_ratio | K6: 0 | L6: 0 | M6: 1023 | N6: 280 | O6: threshold of G bright pixel , the ratio of 3/4 Avg, base is 256 | R6: ISP_DPC_MANUAL_DPC_G_BRIGHT_PIXEL_RATIO | S6: ISP_DPC_AUTO_DPC_G_BRIGHT_PIXEL_RATIO
C7: dpc_b_bright_pixel_ratio | D7: 0 | F7: 0 | G7: 1023 | H7: 280 | I7: 1 | J7: reg_dpc_b_bright_pixel_ratio | K7: 0 | L7: 0 | M7: 1023 | N7: 280 | O7: threshold of B bright pixel , the ratio of 3/4 Avg, base is 256 | R7: ISP_DPC_MANUAL_DPC_B_BRIGHT_PIXEL_RATIO | S7: ISP_DPC_AUTO_DPC_B_BRIGHT_PIXEL_RATIO
C8: N.A | D8: 1 | J8: reg_dpc_r_bright_pixel_upboud_ratio | K8: 0 | L8: 0 | M8: 255 | N8: 236 | O8: R bright threshold high bound , limit max diif will not over saturation , base is 256 min(Diff_Thre, ((4095 - max_bright_gap)*Btight_pixel_upBoud_ratio) / 256) | Q8: ?
C9: N.A | D9: 1 | J9: reg_dpc_g_bright_pixel_upboud_ratio | K9: 0 | L9: 0 | M9: 255 | N9: 236 | O9: G bright threshold high bound , limit max diif will not over saturation , base is 256 min(Diff_Thre, ((4095 - max_bright_gap)*Btight_pixel_upBoud_ratio) / 256) | Q9: ?
C10: N.A | D10: 1 | J10: reg_dpc_b_bright_pixel_upboud_ratio | K10: 0 | L10: 0 | M10: 255 | N10: 236 | O10: B bright threshold high bound , limit max diif will not over saturation , base is 256 min(Diff_Thre, ((4095 - max_bright_gap)*Btight_pixel_upBoud_ratio) / 256) | Q10: ?
A11: DPC dark strength | C11: dpc_r_dark_pixel_ratio | D11: 0 | F11: 0 | G11: 1023 | H11: 200 | I11: 1 | J11: reg_dpc_r_dark_pixel_ratio | K11: 0 | L11: 0 | M11: 1023 | N11: 200 | O11: threshold of R dark pixel , the ratio of 1/4 Avg, base is 256 | R11: ISP_DPC_MANUAL_DPC_R_DARK_PIXEL_RATIO | S11: ISP_DPC_AUTO_DPC_R_DARK_PIXEL_RATIO
C12: dpc_g_dark_pixel_ratio | D12: 0 | F12: 0 | G12: 1023 | H12: 200 | I12: 1 | J12: reg_dpc_r_dark_pixel_ratio | K12: 0 | L12: 0 | M12: 1023 | N12: 200 | O12: threshold of G dark pixel , the ratio of 1/4 Avg, base is 256 | R12: ISP_DPC_MANUAL_DPC_G_DARK_PIXEL_RATIO | S12: ISP_DPC_AUTO_DPC_G_DARK_PIXEL_RATIO
C13: dpc_b_dark_pixel_ratio | D13: 0 | F13: 0 | G13: 1023 | H13: 200 | I13: 1 | J13: reg_dpc_b_dark_pixel_ratio | K13: 0 | L13: 0 | M13: 1023 | N13: 200 | O13: threshold of B dark pixel , the ratio of 1/4 Avg, base is 256 | R13: ISP_DPC_MANUAL_DPC_B_DARK_PIXEL_RATIO | S13: ISP_DPC_AUTO_DPC_B_DARK_PIXEL_RATIO
C14: dpc_r_dark_pixel_mindiff | D14: 0 | F14: 0 | G14: 255 | H14: 11 | I14: 1 | J14: reg_dpc_r_dark_pixel_mindiff | K14: 0 | L14: 0 | M14: 255 | N14: 11 | O14: min limit of R dark threshold , 12 bit data range | R14: ISP_DPC_MANUAL_DPC_R_DARK_PIXEL_MINDIFF | S14: ISP_DPC_AUTO_DPC_R_DARK_PIXEL_MINDIFF
C15: dpc_g_dark_pixel_mindiff | D15: 0 | F15: 0 | G15: 255 | H15: 11 | I15: 1 | J15: reg_dpc_g_dark_pixel_mindiff | K15: 0 | L15: 0 | M15: 255 | N15: 11 | O15: min limit of G dark threshold , 12 bit data range | R15: ISP_DPC_MANUAL_DPC_G_DARK_PIXEL_MINDIFF | S15: ISP_DPC_AUTO_DPC_G_DARK_PIXEL_MINDIFF
C16: dpc_b_dark_pixel_mindiff | D16: 0 | F16: 0 | G16: 255 | H16: 11 | I16: 1 | J16: reg_dpc_b_dark_pixel_mindiff | K16: 0 | L16: 0 | M16: 255 | N16: 11 | O16: min limit of B dark threshold , 12 bit data range | R16: ISP_DPC_MANUAL_DPC_B_DARK_PIXEL_MINDIFF | S16: ISP_DPC_AUTO_DPC_B_DARK_PIXEL_MINDIFF
A17: DPC flat strength | C17: dpc_flat_thre_r | D17: 0 | F17: 0 | G17: 255 | H17: 20 | I17: 1 | J17: reg_dpc_flat_thre_r | K17: 0 | L17: 0 | M17: 255 | N17: 20 | O17: R flat threshold ratio , STD compare with ratio of Avg , base is 256 | R17: ISP_DPC_MANUAL_DPC_FLAT_THRE_R | S17: ISP_DPC_AUTO_DPC_FLAT_THRE_R
C18: dpc_flat_thre_g | D18: 0 | F18: 0 | G18: 255 | H18: 20 | I18: 1 | J18: reg_dpc_flat_thre_g | K18: 0 | L18: 0 | M18: 255 | N18: 20 | O18: G flat threshold ratio , STD compare with ratio of Avg , base is 256 | R18: ISP_DPC_MANUAL_DPC_FLAT_THRE_G | S18: ISP_DPC_AUTO_DPC_FLAT_THRE_G
C19: dpc_flat_thre_b | D19: 0 | F19: 0 | G19: 255 | H19: 20 | I19: 1 | J19: reg_dpc_flat_thre_b | K19: 0 | L19: 0 | M19: 255 | N19: 20 | O19: B flat threshold ratio , STD compare with ratio of Avg , base is 256 | R19: ISP_DPC_MANUAL_DPC_FLAT_THRE_B | S19: ISP_DPC_AUTO_DPC_FLAT_THRE_B
C20: dpc_flat_thre_min_g | D20: 0 | F20: 0 | G20: 255 | H20: 15 | I20: 1 | J20: reg_dpc_flat_thre_min_g | K20: 0 | L20: 0 | M20: 255 | N20: 15 | O20: G non-Flat STD min | R20: ISP_DPC_MANUAL_DPC_FLAT_THRE_MIN_G | S20: ISP_DPC_AUTO_DPC_FLAT_THRE_MIN_G
C21: dpc_flat_thre_min_rb | D21: 0 | F21: 0 | G21: 255 | H21: 15 | I21: 1 | J21: reg_dpc_flat_thre_min_rb | K21: 0 | L21: 0 | M21: 255 | N21: 15 | O21: RG non-Flat STD min | R21: ISP_DPC_MANUAL_DPC_FLAT_THRE_MIN_RB | S21: ISP_DPC_AUTO_DPC_FLAT_THRE_MIN_RB
AK26: ISP_REG_DPC_R_BRIGHT_PIXEL_UPBOUD_RATIO
AK27: ISP_REG_DPC_G_BRIGHT_PIXEL_UPBOUD_RATIO
AK28: ISP_REG_DPC_B_BRIGHT_PIXEL_UPBOUD_RATIO

Sheet Crosstalk
A1: function section | B1: API name | C1: API parameter | D1: UI Level | E1: Calibration | F1: low value | G1: high value | H1: default value | I1: auto | J1: register | K1: dynamic | L1: low value | M1: high value | N1: default value | O1: description | P1: Autogen | Q1: isp_param_def.h | R1: Manual | S1: Auto | T1: cvi_vip_tun_cfg.h | U1: Note
A2: Common | B2: BM_MPI_ISP_SetCrosstalkAttr | C2: ge_enable | D2: 0 | F2: 0 | G2: 1 | H2: 0 | I2: 1 | J2: reg_ge_en | K2: 0 | L2: 0 | M2: 1 | N2: 0 | O2: enable GE | R2: ISP_CROSSTALK_MANUAL_GE_ENABLE | S2: ISP_CROSSTALK_AUTO_GE_ENABLE | T2: __u8 enable; | U2: ISP_CROSSTALK_ENOPTYPE
A3: GE strength | C3: ge_GrGbDiff_Thre_sec1 | D3: 0 | F3: 0 | G3: 4095 | H3: 128 | I3: 0 | J3: reg_ge_thre1 | K3: 0 | L3: 0 | M3: 4095 | N3: 128 | O3: G same channel weighting Thre 1 , larger with more average | Q3: ISP_CROSSTALK_GE_GRGBDIFF_THRE_SEC1 | T3: struct cvi_isp_ge_tun_cfg ge_cfg;
C4: ge_GrGbDiff_Thre_sec2 | D4: 0 | F4: 0 | G4: 4095 | H4: 192 | I4: 0 | J4: reg_ge_thre2 | K4: 0 | L4: 0 | M4: 4095 | N4: 192 | O4: G same channel weighting Thre 2 ( Thre 2 >=Thre 1) , larger with more average | Q4: ISP_CROSSTALK_GE_GRGBDIFF_THRE_SEC2 | T4: struct cvi_isp_ge_tun_cfg ge_cfg;
C5: ge_GrGbDiff_Thre_sec3 | D5: 0 | F5: 0 | G5: 4095 | H5: 224 | I5: 0 | J5: reg_ge_thre3 | K5: 0 | L5: 0 | M5: 4095 | N5: 224 | O5: G same channel weighting Thre 3( Thre 3 >=Thre 2) , larger with more average | Q5: ISP_CROSSTALK_GE_GRGBDIFF_THRE_SEC3 | T5: struct cvi_isp_ge_tun_cfg ge_cfg;
C6: ge_GrGbDiff_Thre_sec4 | D6: 0 | F6: 0 | G6: 4095 | H6: 256 | I6: 0 | J6: reg_ge_thre4 | K6: 0 | L6: 0 | M6: 4095 | N6: 256 | O6: G same channel weighting Thre 4 ( Thre 4 >=Thre 3) , larger with more average | Q6: ISP_CROSSTALK_GE_GRGBDIFF_THRE_SEC4 | T6: struct cvi_isp_ge_tun_cfg ge_cfg;
C7: N.A | D7: 1 | J7: reg_ge_thre1_2 | K7: 0 | L7: 0 | M7: 4095 | N7: 128 | O7: G diff channel weighting Thre 1 , larger with more average | Q7: ? | T7: struct cvi_isp_ge_tun_cfg ge_cfg;
C8: N.A | D8: 1 | J8: reg_ge_thre2_2 | K8: 0 | L8: 0 | M8: 4095 | N8: 192 | O8: G diff channel weighting Thre 2 ( Thre 2 >=Thre 1) , larger with more average | Q8: ? | T8: struct cvi_isp_ge_tun_cfg ge_cfg;
C9: N.A | D9: 1 | J9: reg_ge_thre3_2 | K9: 0 | L9: 0 | M9: 4095 | N9: 224 | O9: G diff channel weighting Thre 3( Thre 3 >=Thre 2) , larger with more average | Q9: ? | T9: struct cvi_isp_ge_tun_cfg ge_cfg;
C10: N.A | D10: 1 | J10: reg_ge_thre4_2 | K10: 0 | L10: 0 | M10: 4095 | N10: 256 | O10: G diff channel weighting Thre 4 ( Thre 4 >=Thre 3) , larger with more average | Q10: ? | T10: struct cvi_isp_ge_tun_cfg ge_cfg;
C11: N.A | D11: 1 | J11: reg_ge_combineweight | K11: 0 | L11: 0 | M11: 8 | N11: 4 | O11: GrGb combine ratio , 8: 100% same chanel G , 0: 50% same channel G , 50% diff channel G | Q11: ? | T11: struct cvi_isp_ge_tun_cfg ge_cfg;
A12: GE flat detection | C12: ge_Flat_Thre1 | D12: 0 | F12: 0 | G12: 4095 | H12: 128 | I12: 0 | J12: reg_ge_thre1_1 | K12: 0 | L12: 0 | M12: 4095 | N12: 128 | O12: STD weighting Thre 1 , larger more flat detect , more GE take effect | Q12: ISP_CROSSTALK_GE_FLAT_THRE1 | T12: struct cvi_isp_ge_tun_cfg ge_cfg;
C13: ge_Flat_Thre2 | D13: 0 | F13: 0 | G13: 4095 | H13: 192 | I13: 0 | J13: reg_ge_thre2_1 | K13: 0 | L13: 0 | M13: 4095 | N13: 192 | O13: STD weighting Thre 2 ( Thre 2 >=Thre 1), larger more flat detect , more GE take effect | Q13: ISP_CROSSTALK_GE_FLAT_THRE2 | T13: struct cvi_isp_ge_tun_cfg ge_cfg;
C14: ge_Flat_Thre3 | D14: 0 | F14: 0 | G14: 4095 | H14: 224 | I14: 0 | J14: reg_ge_thre3_1 | K14: 0 | L14: 0 | M14: 4095 | N14: 224 | O14: STD weighting Thre 3( Thre 3 >=Thre 2), larger more flat detect , more GE take effect | Q14: ISP_CROSSTALK_GE_FLAT_THRE3 | T14: struct cvi_isp_ge_tun_cfg ge_cfg;
C15: ge_Flat_Thre4 | D15: 0 | F15: 0 | G15: 4095 | H15: 256 | I15: 0 | J15: reg_ge_thre4_1 | K15: 0 | L15: 0 | M15: 4095 | N15: 256 | O15: STD weighting Thre 4 ( Thre 4 >=Thre 3), larger more flat detect , more GE take effect | Q15: ISP_CROSSTALK_GE_FLAT_THRE4 | T15: struct cvi_isp_ge_tun_cfg ge_cfg;
A16: GE global strength | C16: ge_strength | D16: 0 | F16: 0 | G16: 256 | H16: 64 | I16: 0 | J16: reg_ge_strength | K16: 0 | L16: 0 | M16: 256 | N16: 64 | O16: GE strength , 256 : 100% GE compensation , 0: 100% current pixel | Q16: ISP_CROSSTALK_GE_STRENGTH | T16: struct cvi_isp_ge_tun_cfg ge_cfg;
E33: 1
E34: 1
E35: 1
E36: 1
E37: 1
E38: 1
E39: 1
E40: 1
E41: 1
E42: 1
E43: 1
E44: 1
... E66: 1

Sheet Cali_CLut
A1: function section | B1: API name | C1: API parameter | D1: low value | E1: high value | F1: default value | G1: auto | H1: register | I1: dynamic | J1: low value | K1: high value | L1: default value | M1: description
A2: CLUT | C2: clut[17][17][17] | D2: 0 | E2: 16777215 | F2: 0 | G2: 0 | M2: clut[R_idx][G_idx][B_idx] = {R target value, G target value, B target value}

Sheet Cali_DPC
A1: function section | B1: API name | C1: API parameter | D1: low value | E1: high value | F1: default value | G1: auto | H1: register | I1: dynamic | J1: low value | K1: high value | L1: default value | M1: description
A2: Calibrated defect pixel coordinates | C2: dpc_coordinate | D2: 0 | E2: 16777216 | F2: 0 | G2: 1 | H2: reg_static_defect[4096] | I2: 0 | J2: 0 | K2: 16777216 | L2: 0 | M2: calibrated static defect coordinates

Sheet Cali_BlackLevel
A1: function section | B1: API name | C1: API parameter | D1: low value | E1: high value | F1: default value | G1: auto | H1: register | I1: dynamic | J1: low value | K1: high value | L1: default value | M1: description
A2: OB value | B2: BM_MPI_ISP_SetBlackLevelAttr | C2: blc_offset_r | D2: 0 | E2: 1023 | F2: 0 | G2: 0
C3: blc_offset_gr | D3: 0 | E3: 1023 | F3: 0 | G3: 0
C4: blc_offset_gb | D4: 0 | E4: 1023 | F4: 0 | G4: 0
C5: blc_offset_b | D5: 0 | E5: 1023 | F5: 0 | G5: 0

Sheet Cali_RadialShading
A1: function section | B1: API name | C1: API parameter | D1: low value | E1: high value | F1: default value | G1: parameter description | H1: auto | I1: register | J1: dynamic | K1: low value | L1: high value | M1: default value | N1: description
A2: common | B2: BM_MPI_RadialShading_Attr_set | C2: lscr_centerx | D2: 0 | E2: 4095 | F2: 0 | H2: 0 | N2: x coordinate of lens center
C3: lscr_centery | D3: 0 | E3: 2047 | F3: 0 | H3: 0 | N3: y coordinate of lens center
A4: lsc gain | B4: BM_MPI_RShadng_LUT | C4: lscr_gain[32] | D4: 0 | E4: 4095 | F4: 512 | H4: 0 | N4: rLSC gain table

Sheet Cali_MeshShading
A1: function section | B1: API name | C1: API parameter | D1: low value | E1: high value | F1: default value | G1: auto | H1: register | I1: dynamic | J1: low value | K1: high value | L1: default value | M1: description
A2: lsc gain | C2: lsc_r_gain[5][1369] | D2: 0 | E2: 4095 | F2: 512 | G2: 1 | M2: mLSC R gain table
C3: lsc_g_gain[5][1369] | D3: 0 | E3: 4095 | F3: 512 | G3: 1 | M3: mLSC G gain table
C4: lsc_b_gain[5][1369] | D4: 0 | E4: 4095 | F4: 512 | G4: 1 | M4: mLSC B gain table

Sheet Sheet1

Sheet Cali_Noise profile
A1: function section | B1: API name | C1: API parameter | D1: low value | E1: high value | F1: default value | G1: parameter description | H1: auto | I1: register | J1: dynamic | K1: low value | L1: high value | M1: default value | N1: description
A2: Noise profile | C2: noise_profile[16][4][2] | D2: 0 | E2: 4095 | F2: 0 | H2: 1 | I2: N.A | K2: 0 | L2: 4095 | N2: 16x2 number of entries of RGGB channels containing 16 parameters [a, b] associated with ISOs ranged from 100, 200, …, 3276800

Sheet Cali_AWB
A1: function section | B1: API name | C1: API parameter | D1: low value | E1: high value | F1: default value | G1: auto | H1: register | I1: dynamic | J1: low value | K1: high value | L1: default value | M1: description
A2: WB gain | C2: wbg_rgain[5] | D2: 0 | E2: 16383 | F2: 1024 | G2: 1
C3: wbg_ggain[5] | D3: 0 | E3: 16383 | F3: 1024 | G3: 1
C4: wbg_bgain[5] | D4: 0 | E4: 16383 | F4: 1024 | G4: 1

Sheet TNR
A1: function section | B1: API name | C1: API parameter | D1: UI Level | E1: Calibration | F1: low value | G1: high value | H1: default value | I1: auto | J1: register | K1: dynamic | L1: low value | M1: high value | N1: default value | O1: description
C2: tnr_enable | J2: reg_manr_enable | K2: 1 | L2: 0 | M2: 1 | N2: 0 | O2: manr_enable set 0 = bypass
C3: tnr_merge_mode | F3: 0 | G3: 1 | H3: 0 | I3: 1 | J3: reg_mmap_mrg_mode | K3: 1 | L3: 0 | M3: 1 | N3: 0
C4: tnr_merge_mode_alpha | F4: 0 | G4: 1 | H4: 0 | I4: 1 | J4: reg_mmap_mrg_alph | K4: 1 | L4: 0 | M4: 255 | N4: 0
C5: N.A | J5: reg_rgbmap_w_bit | K5: 0 | L5: 3 | M5: 7 | N5: 3
C6: N.A | J6: reg_rgbmap_h_bit | K6: 0 | L6: 3 | M6: 7 | N6: 3
A7: global strength | C7: tnr_path0_strength | F7: 0 | G7: 255 | H7: 16 | I7: 1 | J7: reg_mmap_0_map_gain | K7: 1 | L7: 0 | M7: 255 | N7: 16
C8: tnr_path0_map_thd_l | F8: 0 | G8: 255 | H8: 0 | I8: 1 | J8: reg_mmap_0_map_thd_l | K8: 1 | L8: 0 | M8: 255 | N8: 0
C9: tnr_path0_map_thd_h | F9: 0 | G9: 255 | H9: 255 | I9: 1 | J9: reg_mmap_0_map_thd_h | K9: 1 | L9: 0 | M9: 255 | N9: 255
C10: tnr_path1_strength | F10: 0 | G10: 255 | H10: 16 | I10: 1 | J10: reg_mmap_1_map_gain | K10: 1 | L10: 0 | M10: 255 | N10: 16
C11: tnr_path1_map_thd_l | F11: 0 | G11: 255 | H11: 0 | I11: 1 | J11: reg_mmap_1_map_thd_l | K11: 1 | L11: 0 | M11: 255 | N11: 0
C12: tnr_path1_map_thd_h | F12: 0 | G12: 255 | H12: 255 | I12: 1 | J12: reg_mmap_1_map_thd_h | K12: 1 | L12: 0 | M12: 255 | N12: 255
A13: noise model | C13: tnr_path0_r_noise_level | F13: 0 | G13: 255 | H13: 64 | I13: 1 | J13: reg_mmap_0_ns_slope_r | K13: 1 | L13: 0 | M13: 1023 | N13: 0 | O13: 0 ~ 255 mapping to 0 noise std ~ 3.984375 std
J14: reg_mmap_0_ns_luma_th0_r | K14: 1 | L14: 0 | M14: 4095 | N14: 0
J15: reg_mmap_0_ns_low_offset_r | K15: 1 | L15: 0 | M15: 4095 | N15: 0
J16: reg_mmap_0_ns_high_offset_r | K16: 1 | L16: 0 | M16: 4095 | N16: 0
C17: tnr_path0_g_noise_level | F17: 0 | G17: 255 | H17: 64 | I17: 1 | J17: reg_mmap_0_ns_slope_g | K17: 1 | L17: 0 | M17: 1023 | N17: 0 | O17: 0 ~ 255 mapping to 0 noise std ~ 3.984375 std
J18: reg_mmap_0_ns_luma_th0_g | K18: 1 | L18: 0 | M18: 4095 | N18: 0
J19: reg_mmap_0_ns_low_offset_g | K19: 1 | L19: 0 | M19: 4095 | N19: 0
J20: reg_mmap_0_ns_high_offset_g | K20: 1 | L20: 0 | M20: 4095 | N20: 0
C21: tnr_path0_b_noise_level | F21: 0 | G21: 255 | H21: 64 | I21: 1 | J21: reg_mmap_0_ns_slope_b | K21: 1 | L21: 0 | M21: 1023 | N21: 0 | O21: 0 ~ 255 mapping to 0 noise std ~ 3.984375 std
J22: reg_mmap_0_ns_luma_th0_b | K22: 1 | L22: 0 | M22: 4095 | N22: 0
J23: reg_mmap_0_ns_low_offset_b | K23: 1 | L23: 0 | M23: 4095 | N23: 0
J24: reg_mmap_0_ns_high_offset_b | K24: 1 | L24: 0 | M24: 4095 | N24: 0
C25: tnr_path1_r_noise_level | F25: 0 | G25: 255 | H25: 64 | I25: 1 | J25: reg_mmap_1_ns_slope_r | K25: 1 | L25: 0 | M25: 1023 | N25: 0 | O25: 0 ~ 255 mapping to 0 noise std ~ 3.984375 std
J26: reg_mmap_1_ns_luma_th0_r | K26: 1 | L26: 0 | M26: 4095 | N26: 0
J27: reg_mmap_1_ns_low_offset_r | K27: 1 | L27: 0 | M27: 4095 | N27: 0
J28: reg_mmap_1_ns_high_offset_r | K28: 1 | L28: 0 | M28: 4095 | N28: 0
C29: tnr_path1_g_noise_level | F29: 0 | G29: 255 | H29: 64 | I29: 1 | J29: reg_mmap_1_ns_slope_g | K29: 1 | L29: 0 | M29: 1023 | N29: 0 | O29: 0 ~ 255 mapping to 0 noise std ~ 3.984375 std
J30: reg_mmap_1_ns_luma_th0_g | K30: 1 | L30: 0 | M30: 4095 | N30: 0
J31: reg_mmap_1_ns_low_offset_g | K31: 1 | L31: 0 | M31: 4095 | N31: 0
J32: reg_mmap_1_ns_high_offset_g | K32: 1 | L32: 0 | M32: 4095 | N32: 0
C33: tnr_path1_b_noise_level | F33: 0 | G33: 255 | H33: 64 | I33: 1 | J33: reg_mmap_1_ns_slope_b | K33: 1 | L33: 0 | M33: 1023 | N33: 0 | O33: 0 ~ 255 mapping to 0 noise std ~ 3.984375 std
J34: reg_mmap_1_ns_luma_th0_b | K34: 1 | L34: 0 | M34: 4095 | N34: 0
J35: reg_mmap_1_ns_low_offset_b | K35: 1 | L35: 0 | M35: 4095 | N35: 0
J36: reg_mmap_1_ns_high_offset_b | K36: 1 | L36: 0 | M36: 4095 | N36: 0
A37: gain change compensation | C37: N.A | J37: reg_mmap_0_gain_ratio_r | K37: 1 | L37: 0 | M37: 65535 | N37: 4096
C38: N.A | J38: reg_mmap_0_gain_ratio_g | K38: 1 | L38: 0 | M38: 65535 | N38: 4096
C39: N.A | J39: reg_mmap_0_gain_ratio_b | K39: 1 | L39: 0 | M39: 65535 | N39: 4096
C40: N.A | J40: reg_mmap_1_gain_ratio_r | K40: 1 | L40: 0 | M40: 65535 | N40: 4096
...

Sheet Cali_AELV
A1: function section | B1: API name | C1: API parameter | D1: low value | E1: high value | F1: default value | G1: auto | H1: register | I1: dynamic | J1: low value | K1: high value | L1: default value | M1: description
C2: TargetY | D2: 0 | E2: 255 | F2: 64 | G2: 0 | H2: u8TargetY | I2: 1 | J2: 0 | K2: 255 | L2: 64 | M2: 目標亮度，預設64。 取值范围：[0x0, 0xFF]。
C3: AEAvgMode | D3: 0 | E3: 1 | F3: 1 | G3: 0 | H3: enAEAvgMode | I3: 1 | J3: 0 | K3: 1 | L3: 1 | M3: 計算平均值的來源，預設ISP_AE_AVG_G_MODE。 取值范围：[ISP_AE_AVG_LUM_MODE, ISP_AE_AVG_G_MODE]。
C4: LightValue | D4: -15 | E4: 18 | F4: 10 | G4: 0 | H4: S8LightValue | I4: 1 | J4: -15 | K4: 18 | L4: 10 | M4: Light value (ISO100時，EV=LV)，預設10。
C5: IrisFNO | D5: 0 | E5: 10 | F5: 8 | G5: 0 | H5: enIrisFNO | I5: 1 | J5: 0 | K5: 10 | L5: 8 | M5: 节点光圈 F 值大小，仅支持 P-Iris，不支持 DC-Iris。預設ISP_IRIS_F_NO_2_0。 取值范围：[ISP_IRIS_F_NO_32_0, ISP_IRIS_F_NO_1_0]。
C6: ExposureTime(us) | D6: 0 | E6: 4294967295 | F6: 4000 | G6: 0 | H6: u32ExpTime | I6: 1 | J6: 0 | K6: 4294967295 | L6: 4000 | M6: 曝光时间，单位为微秒(us)，僅針對長曝進行校正。 預設1/250s。取值范围：[0x0, 0xFFFFFFFF]。
C7: SensorGain | D7: 0 | E7: 240 | F7: 0 | G7: 0 | H7: u8SensorGain | I7: 1 | J7: 0 | K7: 240 | L7: 0 | M7: Sensor Gain值。 (在此以IMX290為例) 取值范围：[0x0, 0xF0]。

Sheet Cali_CCM
A1: function section | B1: API name | C1: API parameter | D1: low value | E1: high value | F1: default value | G1: auto | H1: register | I1: dynamic | J1: low value | K1: high value | L1: default value | M1: description
A2: ccm matrix | C2: ccm[5][9] | D2: 0 | E2: 16383 | F2: 1024 | G2: 1
D3: 0 | E3: 16383 | F3: 0 | G3: 1
D4: 0 | E4: 16383 | F4: 0 | G4: 1
D5: 0 | E5: 16383 | F5: 0 | G5: 1
D6: 0 | E6: 16383 | F6: 1024 | G6: 1
D7: 0 | E7: 16383 | F7: 0 | G7: 1
D8: 0 | E8: 16383 | F8: 0 | G8: 1
D9: 0 | E9: 16383 | F9: 0 | G9: 1
D10: 0 | E10: 16383 | F10: 1024 | G10: 1

Sheet Sharpen
A1: function section | B1: API name | C1: API parameter | D1: UI Level | E1: Calibration | F1: low value | G1: high value | H1: default value | I1: auto | J1: register | K1: dynamic | L1: low value | M1: high value | N1: default value | O1: description
A2: common | B2: BM_MPI_ISP_SetSharpenAttr | C2: ee_enable | F2: 0 | G2: 1 | H2: 0 | I2: 1 | J2: reg_ee_enable | K2: 1 | L2: 0 | M2: 1 | N2: 0 | O2: ee function enable
C3: ee_dbg_mode | F3: 0 | G3: 11 | H3: 0 | I3: 0 | J3: reg_ee_dbg_mode | K3: 0 | L3: 0 | M3: 11 | N3: 0 | O3: 0~11 , 0 : EE result output 1: total_delta debug: 2: total_delta positive debug: 3: total_delta negative debug: 4. adptgain_lumawgt debug: 5. adptgain_deltawgt debug: 6. adptgain_wgt debug: 7. dirdet_wgt debug: 8. dgr4_000 debug: 9. dgr4_090 debug: 10. dgr4_045 debug: 11. dgr4_135 debug:
C4: ee_dbg_mode_level_shift | F4: 0 | G4: 8 | H4: 0 | I4: 0 | J4: reg_ee_dbg_mode_level_shift | K4: 0 | L4: 0 | M4: 8 | N4: 0 | O4: 0~8
A5: edge direction detection | C5: N.A | J5: reg_ee_dirdet_lpf_bldwgt | K5: 1 | L5: 0 | M5: 32 | N5: 0 | O5: blending 3x3 lpf ds weight and 5x5 ds weight. 0 biases 5x5 ds weight, 1 bias 3x3 ds weight
C6: N.A | J6: reg_ee_dirdet_min_gain | K6: 1 | L6: 0 | M6: 127 | N6: 16 | O6: ee direction detection min sad gain
C7: ee_dirdet_dirgain | F7: 0 | G7: 255 | H7: 16 | I7: 1 | J7: reg_ee_dirdet_dirgain | K7: 1 | L7: 0 | M7: 255 | N7: 16 | O7: ee direction detection direction weight adjust gain
C8: ee_dirdet_dirthrd | F8: 0 | G8: 255 | H8: 0 | I8: 1 | J8: reg_ee_dirdet_dirthrd | K8: 1 | L8: 0 | M8: 255 | N8: 0 | O8: ee direction detection direction weight adjust threshold
C9: ee_dirdet_subgain | F9: 0 | G9: 255 | H9: 16 | I9: 1 | J9: reg_ee_dirdet_subgain | K9: 1 | L9: 0 | M9: 255 | N9: 16 | O9: ee direction detection sub direction weight adjust gain
C10: ee_dirdet_subthrd | F10: 0 | G10: 255 | H10: 0 | I10: 1 | J10: reg_ee_dirdet_subthrd | K10: 1 | L10: 0 | M10: 255 | N10: 0 | O10: ee direction detection sub direction weight adjust threshold
C11: N.A | J11: reg_ee_dirdet_sadnorm_tgt | K11: 1 | L11: 0 | M11: 255 | N11: 255 | O11: ee direction detection sad normaization target
C12: N.A | J12: reg_ee_dirdet_min_gain_adpt_en | K12: 1 | L12: 0 | M12: 1 | N12: 0 | O12: ee direction detection min gain adaptive enable
C13: N.A | J13: reg_ee_dirsub_wgt_coring_thrd | K13: 1 | L13: 0 | M13: 4095 | N13: 0 | O13: ee direction detection sub weight coring threshold
C14: N.A | J14: reg_ee_dirdet_wgt_coring_thrd | K14: 1 | L14: 0 | M14: 4095 | N14: 0 | O14: ee direction detection dir weight coring threshold
C15: N.A | J15: reg_ee_dirdet_dgradpt_trans_slop | K15: 1 | L15: 0 | M15: 15 | N15: 4 | O15: ee direction detection degree adaptive transfer slpoe
C16: N.A | J16: reg_ee_dirdet_midledir_gain | K16: 1 | L16: 0 | M16: 53 | N16: tune | O16: ee direction detection middle degree gain control
C17: N.A | J17: reg_ee_dirdet_aligndir_gain | K17: 1 | L17: 0 | M17: 53 | N17: tune | O17: ee direction detection align degree gain control
A18: filters bank | C18: ee_dircal_dgr4_dir_adjgain | F18: 0 | G18: 63 | H18: 16 | I18: 0 | J18: reg_ee_dircal_dgr4_dir_adjgain | K18: 1 | L18: 0 | M18: 63 | N18: 16 | O18: ee direction filter adjust gain direction
C19: N.A | J19: reg_ee_dircal_dgr4_000_norgain | K19: 1 | L19: 0 | M19: 1023 | N19: 128 | O19: ee direction filter normalize gain degree 0
C20: N.A | J20: reg_ee_dircal_dgr4_045_norgain | K20: 1 | L20: 0 | M20: 1023 | N20: 76 | O20: ee direction filter normalize gain degree 45
C21: N.A | J21: reg_ee_dircal_dgr4_090_norgain | K21: 1 | L21: 0 | M21: 1023 | N21: 128 | O21: ee direction filter normalize gain degree 90
C22: N.A | J22: reg_ee_dircal_dgr4_135_norgain | K22: 1 | L22: 0 | M22: 1023 | N22: 76 | O22: ee direction filter normalize gain degree 135
C23: N.A | J23: reg_ee_dircal_dgr4_nod_norgain | K23: 1 | L23: 0 | M23: 1023 | N23: 77 | O23: ee direction filter normalize gain no direction
C24: N.A | J24: reg_ee_dircal_dgr4_000_adjgain | K24: 1 | L24: 0 | M24: 63 | N24: 16 | O24: ee direction filter adjust gain degree 0
C25: N.A | J25: reg_ee_dircal_dgr4_045_adjgain | K25: 1 | L25: 0 | M25: 63 | N25: 16 | O25: ee direction filter adjust gain degree 45
C26: N.A | J26: reg_ee_dircal_dgr4_090_adjgain | K26: 1 | L26: 0 | M26: 63 | N26: 16 | O26: ee direction filter adjust gain degree 90
C27: N.A | J27: reg_ee_dircal_dgr4_135_adjgain | K27: 1 | L27: 0 | M27: 63 | N27: 16 | O27: ee direction filter adjust gain degree 135
C28: N.A | J28: reg_ee_dircal_dgr4_nod_adjgain | K28: 1 | L28: 0 | M28: 63 | N28: 16 | O28: ee direction filter adjust gain no direction
C29: N.A | J29: reg_ee_dircal_dgr4_000_coringth | K29: 1 | L29: 0 | M29: 255 | N29: 0 | O29: ee direction filter coring threshold degree 0
C30: N.A | J30: reg_ee_dircal_dgr4_045_coringth | K30: 1 | L30: 0 | M30: 255 | N30: 0 | O30: ee direction filter coring threshold degree 45
... C33: N.A | J33: reg_ee_dircal_dgr4_nod_coringth | K33: 1 | L33: 0 | M33: 255 | N33: 0 | O33: ee direction filter coring threshold no direction
C34: ee_edge_freq | F34: 0 | G34: 511 | H34: 0 | I34: 1 | J34: reg_ee_dircal_dgr4_filter000_w1 | K34: 1 | L34: 0 | M34: 511 | N34: 0 | O34: ee direction filter weight 1 degree 0
J35: reg_ee_dircal_dgr4_filter000_w2 | K35: 1 | L35: 0 | M35: 511 | N35: -1 | O35: ee direction filter weight 2 degree 0
J36: reg_ee_dircal_dgr4_filter000_w3 | K36: 1 | L36: 0 | M36: 511 | N36: -2 | O36: ee direction filter weight 3 degree 0
J37: reg_ee_dircal_dgr4_filter000_w4 | K37: 1 | L37: 0 | M37: 511 | N37: 0 | O37: ee direction filter weight 4 degree 0
J38: reg_ee_dircal_dgr4_filter000_w5 | K38: 1 | L38: 0 | M38: 511 | N38: -2 | O38: ee direction filter weight 5 degree 0
J39: reg_ee_dircal_dgr4_filter000_w6 | K39: 1 | L39: 0 | M39: 511 | N39: -4 | O39: ee direction filter weight 6 degree 0
J40: reg_ee_dircal_dgr4_filter000_w7 | K40: 1 | L40: 0 | M40: 511 | N40: 0 | O40: ee direction filter weight 7 degree 0
J41: reg_ee_dircal_dgr4_filter000_w8 | K41: 1 | L41: 0 | M41: 511 | N41: 6 | O41: ee direction filter weight 8 degree 0
J42: reg_ee_dircal_dgr4_filter000_w9 | K42: 1 | L42: 0 | M42: 511 | N42: 12 | O42: ee direction filter weight 9 degree 0
...

Sheet FSWDR
A1: function section | B1: API name | C1: API parameter | D1: UI Level | E1: Calibration | F1: low value | G1: high value | H1: default value | I1: auto | J1: register | K1: dynamic | L1: low value | M1: high value | N1: default value | O1: description
A2: common | B2: BM_MPI_ISP_SetFSWDRAttr | C2: fs_enable | F2: 0 | G2: 1 | H2: 0 | I2: 1 | J2: reg_fs_enable | K2: 1 | L2: 0 | M2: 1 | N2: 0 | O2: Enable long short frame fusion
C3: fs_mc_enable | F3: 0 | G3: 1 | H3: 0 | I3: 1 | J3: reg_fs_mc_enable | K3: 1 | L3: 0 | M3: 1 | N3: 0 | O3: Motion refernce short exposure
C4: fs_out_sel | F4: 0 | G4: 0 | H4: 3 | I4: 1 | J4: reg_fs_out_sel | K4: 1 | L4: 0 | M4: 3 | N4: 0 | O4: Selection our frame (short, short expand, long, fusion)
A5: HDR exposure related | C5: fs_ls_gain | F5: 64 | G5: 16383 | H5: 1024 | I5: 1 | J5: reg_fs_ls_gain | K5: 1 | L5: 64 | M5: 16383 | N5: 1024 | O5: Gain of exposure (8.6)
C6: fs_s_max | F6: 0 | G6: 104875 | H6: 65535 | I6: 1 | J6: reg_fs_s_max | K6: 1 | L6: 0 | M6: 104875 | N6: 65535 | O6: Max of short exposrue
A7: fusion curve | C7: fs_luma_thd_l | F7: 0 | G7: 4095 | H7: 3900 | I7: 1 | J7: reg_fs_luma_thd_l | K7: 1 | L7: 0 | M7: 4095 | N7: 3900 | O7: Lower bound for luma-adpative fusion
C8: fs_luma_thd_h | F8: 0 | G8: 4095 | H8: 4095 | I8: 1 | J8: reg_fs_luma_thd_h | K8: 1 | L8: 0 | M8: 4095 | N8: 4095 | O8: Upper bound for luma-adpative fusion
C9: fs_wgt_max | F9: 0 | G9: 255 | H9: 255 | I9: 1 | J9: reg_fs_wgt_max | K9: 1 | L9: 0 | M9: 255 | N9: 255 | O9: Fusion weight upper bound
C10: fs_wgt_min | F10: 0 | G10: 255 | H10: 0 | I10: 1 | J10: reg_fs_wgt_min | K10: 1 | L10: 0 | M10: 255 | N10: 0 | O10: Fusion weight lower bound
C11: N.A | J11: reg_fs_wgt_slp | K11: 1 | L11: -262144 | M11: 262143 | N11: 1339 | O11: Calculate by SW lib. Fixed-point (s8.10). (reg_fs_wgt_max - reg_fs_wgt_min) / (reg_fs_luma_thd_h reg_fs_luma_thd_l)

Sheet DRC
A1: function section | B1: API name | C1: API parameter | D1: UI Level | E1: Calibration | F1: low value | G1: high value | H1: default value | I1: auto | J1: register | K1: dynamic | L1: low value | M1: high value | N1: default value | O1: description
A2: common | B2: BM_MPI_ISP_SetDRCAttr | C2: ltm_enable | F2: 0 | G2: 1 | H2: 0 | J2: reg_ltm_enable | K2: 1 | L2: 0 | M2: 1 | N2: 0 | O2: Enable local tone mapping
C3: lmap_enable | F3: 0 | G3: 1 | H3: 0 | J3: reg_lmap_enable | K3: 1 | L3: 0 | M3: 1 | N3: 0 | O3: Enable luma map calculation
C4: ltm_dark_enh_en | F4: 0 | G4: 1 | H4: 0 | J4: reg_ltm_dark_enh_en | K4: 1 | L4: 0 | M4: 1 | N4: 0 | O4: Dark strength enhancement enable
C5: ltm_brit_enh_en | F5: 0 | G5: 1 | H5: 0 | J5: reg_ltm_brit_enh_en | K5: 1 | L5: 0 | M5: 1 | N5: 0 | O5: Bright strength enhancement enable
C6: ltm_dark_lce_en | F6: 0 | G6: 1 | H6: 0 | J6: reg_ltm_dark_lce_en | K6: 1 | L6: 0 | M6: 1 | N6: 0 | O6: Dark Local contrast enhancement enable
C7: ltm_brit_lce_en | F7: 0 | G7: 1 | H7: 0 | J7: reg_ltm_brit_lce_en | K7: 1 | L7: 0 | M7: 1 | N7: 0 | O7: Bright Local contrast enhancement enable
A8: Luma map | C8: N.A | J8: reg_lmap_w_grid_num | K8: 1 | L8: 0 | M8: 511 | N8: 120 | O8: Luma map width grid size
C9: N.A | J9: reg_lmap_h_grid_num | K9: 1 | L9: 0 | M9: 511 | N9: 68 | O9: Luma map height grid size
C10: lmap_w_bit | F10: 0 | G10: 7 | H10: 4 | J10: reg_lmap_w_bit | K10: 1 | L10: 0 | M10: 7 | N10: 4 | O10: Luma map grid width bit. 4 means grid width 16.
C11: lmap_h_bit | F11: 0 | G11: 7 | H11: 4 | J11: reg_lmap_h_bit | K11: 1 | L11: 0 | M11: 7 | N11: 4 | O11: Luma map grid height bit. 4 means grid height 16.
C12: lmap_thd_l | F12: 0 | G12: 4095 | H12: 0 | J12: reg_lmap_thd_l | K12: 1 | L12: 0 | M12: 4095 | N12: 0 | O12: Lower bound threshold for luma map
C13: lmap_thd_h | F13: 0 | G13: 4095 | H13: 4095 | J13: reg_lmap_thd_h | K13: 1 | L13: 0 | M13: 4095 | N13: 4095 | O13: Upper bound threshold for luma map, must > reg_lmap_thd_l.
C14: N.A | J14: reg_lmap_y_mode | K14: 0 | L14: 0 | M14: 3 | N14: 0 | O14: Luma mode: (0: y), (1: max), (2: avg), (3: max-min avg)
A15: Demosaic | C15: N.A | J15: reg_ltm_cfa_hflp_strth | K15: 1 | L15: 0 | M15: 255 | N15: 255 | O15: Weighted blending strength
C16: N.A | J16: reg_ltm_cfa_np_ymin | K16: 1 | L16: 0 | M16: 4095 | N16: 0 | O16: minimum Y to calculate noise level
C17: N.A | J17: reg_ltm_cfa_np_yslope | K17: 1 | L17: 0 | M17: 255 | N17: 0 | O17: slope of NP-Y
C18: N.A | J18: reg_ltm_cfa_np_low | K18: 1 | L18: 0 | M18: 255 | N18: 0 | O18: minimum noise level of minimum Y
C19: N.A | J19: reg_ltm_cfa_np_high | K19: 1 | L19: 0 | M19: 255 | N19: 3 | O19: maximum noise level of Y
C20: N.A | J20: reg_ltm_cfa_diffthd_min | K20: 1 | L20: 0 | M20: 4095 | N20: 520 | O20: minimum HV difference
C21: N.A | J21: reg_ltm_cfa_diffthd_slope | K21: 1 | L21: 0 | M21: 255 | N21: 81 | O21: slope of weighting-HV_Diff
C22: N.A | J22: reg_ltm_cfa_diffw_low | K22: 1 | L22: 0 | M22: 255 | N22: 0 | O22: minimum weighting of minimum HV_Diff
C23: N.A | J23: reg_ltm_cfa_diffw_high | K23: 1 | L23: 0 | M23: 255 | N23: 255 | O23: maximum weighting of HV_Diff
